<?xml version="1.0"?>
<robot name="dragon">
  <link name="world">
    <origin xyz="0 0 0" rpy="0 0 0"/>
  </link>   
  <link name="body">
    <visual>
      <geometry>
        <mesh filename="package://dragon_description/meshes/body_unit_m.stl"/>
      </geometry>
      <origin xyz="0 0 0" rpy="1.570796327 0 1.570796327"/>
    </visual>
    <collision>
      <geometry>
        <mesh filename="package://dragon_description/meshes/body_unit_m.stl"/>
      </geometry>
      <origin xyz="0 0 0" rpy="1.570796327 0 1.570796327"/>
    </collision>
    <inertial>
      <origin xyz="-0.294161 -0.000952 1.016932" rpy="1.570796327 0 1.570796327"/>
      <mass value="9.9629698"/>
      <inertia ixx="0.506565255" ixy="-0.000206853" ixz="-0.004881012" iyy="0.516386594" iyz="0.006092892" izz="0.074902421"/>
    </inertial>
  </link>
  <joint name="floating_joint" type="fixed">
    <parent link="world"/>
    <child link="body"/>
    <origin xyz="0 0 0.61" rpy="0 0 0"/>
    <limit lower="-10" upper="10" effort="1000" velocity="10"/>
  <dynamics damping="0.1" friction="0"/>  
  <safety_controller k_position="100" k_velocity="100" soft_lower_limit="-10.698" soft_upper_limit="10.785" />
</joint>

<link name="left_front_upper">
  <visual>
    <geometry>
      <mesh filename="package://dragon_description/meshes/body_part.stl"/>
    </geometry>
    <origin xyz="0 0 0" rpy="1.570796327 0 3.1415926" />
  </visual>
  <collision>
    <geometry>
      <mesh filename="package://dragon_description/meshes/body_part.stl"/>
    </geometry>
    <origin xyz="0 0 0" rpy="1.570796327 0 3.1415926" />
  </collision>
  <inertial>
    <origin xyz="0 0 0" rpy="1.570796327 0 3.1415926" />
    <mass value="0.67833686"/>
    <inertia ixx="0.000458198" ixy="-0.000198409" ixz="-0.000000564" iyy="0.005121443" iyz="-0.000002605" izz="0.00519021"/>
  </inertial>
</link>
<joint name="left_front_fixed" type="fixed">
  <parent link="body"/>
  <child link="left_front_upper"/>
  <origin xyz="0 0.135 -0.02" rpy="0 0 0"/>
</joint>

<link name="right_front_upper">
  <visual>
    <geometry>
      <mesh filename="package://dragon_description/meshes/body_part.stl"/>
    </geometry>
    <origin xyz="0 0 0" rpy="1.570796327 0 3.1415926" />
  </visual>
  <collision>
    <geometry>
      <mesh filename="package://dragon_description/meshes/body_part.stl"/>
    </geometry>
    <origin xyz="0 0 0" rpy="1.570796327 0 3.1415926" />
  </collision>
  <inertial>
    <origin xyz="0 0 0" rpy="1.570796327 0 3.1415926" />
    <mass value="0.67833686"/>
    <inertia ixx="0.000458198" ixy="-0.000198409" ixz="-0.000000564" iyy="0.005121443" iyz="-0.000002605" izz="0.00519021"/>
  </inertial>
</link>
<joint name="right_front_fixed" type="fixed">
  <parent link="body"/>
  <child link="right_front_upper"/>
  <origin xyz="0 -0.135 -0.02" rpy="0 0 0"/>
</joint>

<link name="left_back_upper">
  <visual>
    <geometry>
      <mesh filename="package://dragon_description/meshes/body_part.stl"/>
    </geometry>
    <origin xyz="0 0 0" rpy="1.570796327 0 0" />
  </visual>
  <collision>
    <geometry>
      <mesh filename="package://dragon_description/meshes/body_part.stl"/>
    </geometry>
    <origin xyz="0 0 0" rpy="1.570796327 0 0" />
  </collision>
  <inertial>
    <origin xyz="0.1 0 0.02" rpy="1.570796327 0 0" />
    <mass value="0.67833686"/>
    <inertia ixx="0.000458198" ixy="-0.000198409" ixz="-0.000000564" iyy="0.005121443" iyz="-0.000002605" izz="0.00519021"/>
  </inertial>
</link>
<joint name="left_back_fixed" type="fixed">
  <parent link="body"/>
  <child link="left_back_upper"/>
  <origin xyz="-0.3 0.15 0.045" rpy="0 0 0"/>
</joint>

<link name="right_back_upper">
  <visual>
    <geometry>
      <mesh filename="package://dragon_description/meshes/body_part.stl"/>
    </geometry>
    <origin xyz="0 0 0" rpy="1.570796327 0 0" />
  </visual>
  <collision>
    <geometry>
      <mesh filename="package://dragon_description/meshes/body_part.stl"/>
    </geometry>
    <origin xyz="0 0 0" rpy="1.570796327 0 0" />
  </collision>
  <inertial>
    <origin xyz="0.1 0 0.02" rpy="1.570796327 0 0" />
    <mass value="0.67833686"/>
    <inertia ixx="0.000458198" ixy="-0.000198409" ixz="-0.000000564" iyy="0.005121443" iyz="-0.000002605" izz="0.00519021"/>
  </inertial>
</link>
<joint name="right_back_fixed" type="fixed">
  <parent link="body"/>
  <child link="right_back_upper"/>
  <origin xyz="-0.3 -0.15 0.045" rpy="0 0 0"/>
</joint>

<link name="left_front_leg">
  <visual>
    <geometry>
      <mesh filename="package://dragon_description/meshes/upper_leg.stl"/>
    </geometry>
    <origin xyz="0 0 0" rpy="1.570796327 0 3.1415926" />
  </visual>
  <collision>
    <geometry>
      <mesh filename="package://dragon_description/meshes/upper_leg.stl"/>
    </geometry>
    <origin xyz="0 0 0" rpy="1.570796327 0 3.1415926" />
  </collision>
  <inertial>
    <origin xyz="0 0 -0.1325" rpy="1.570796327 0 3.1415926" />
    <mass value="0.58240446"/>
    <inertia ixx="0.004146058" ixy="0.000104152" ixz="-0.000001286" iyy="0.000305157" iyz="-0.00000174" izz="0.0042282"/>
  </inertial>
</link>
<joint name="left_front_hip" type="revolute">
  <parent link="left_front_upper"/>
  <child link="left_front_leg"/>
  <axis xyz="0 1 0"/>
  <origin xyz="0 0 0" rpy="0 0 0"/>
  <dynamics damping="0.1" friction="0"/>
  <limit lower="-0.698131689" upper="0.78539815" effort="100" velocity="10"/>
  <safety_controller k_position="100" k_velocity="100" soft_lower_limit="-10.698" soft_upper_limit="10.785" />
</joint>

<link name="right_front_leg">
  <visual>
    <geometry>
      <mesh filename="package://dragon_description/meshes/upper_leg.stl"/>
    </geometry>
    <origin xyz="0 0 0" rpy="1.570796327 0 3.1415926" />
  </visual>
  <collision>
    <geometry>
      <mesh filename="package://dragon_description/meshes/upper_leg.stl"/>
    </geometry>
    <origin xyz="0 0 0" rpy="1.570796327 0 3.1415926" />
  </collision>
  <inertial>
    <origin xyz="0 0 -0.1325" rpy="1.570796327 0 3.1415926" />
    <mass value="0.58240446"/>
    <inertia ixx="0.004146058" ixy="0.000104152" ixz="-0.000001286" iyy="0.000305157" iyz="-0.00000174" izz="0.0042282"/>
  </inertial>
</link>
<joint name="right_front_hip" type="revolute">
  <parent link="right_front_upper"/>
  <child link="right_front_leg"/>
  <axis xyz="0 1 0"/>
  <origin xyz="0 0 0" rpy="0 0 0"/>
  <dynamics damping="0.1" friction="0"/>
  <limit lower="-0.698131689" upper="0.78539815" effort="100" velocity="10"/>
  <safety_controller k_position="100" k_velocity="100" soft_lower_limit="-10.698" soft_upper_limit="10.785" />
</joint>

<link name="left_back_leg">
  <visual>
    <geometry>
      <mesh filename="package://dragon_description/meshes/upper_leg.stl"/>
    </geometry>
    <origin xyz="0 0 0" rpy="1.570796327 0 0" />
  </visual>
  <collision>
    <geometry>
      <mesh filename="package://dragon_description/meshes/upper_leg.stl"/>
    </geometry>
    <origin xyz="0 0 0" rpy="1.570796327 0 0" />
  </collision>
  <inertial>
    <origin xyz="0 0 -0.1325" rpy="1.570796327 0 0" />
    <mass value="0.58240446"/>
    <inertia ixx="0.004146058" ixy="0.000104152" ixz="-0.000001286" iyy="0.000305157" iyz="-0.00000174" izz="0.0042282"/>
  </inertial>
</link>
<joint name="left_back_hip" type="revolute">
  <parent link="left_back_upper"/>
  <child link="left_back_leg"/>
  <origin xyz="0 0 0" rpy="0 0 0"/>
  <axis xyz="0 1 0"/>
  <dynamics damping="0.1" friction="0"/>
  <limit lower="-0.78539815" upper="0.698131689" effort="100" velocity="10"/>
  <safety_controller k_position="100" k_velocity="100" soft_lower_limit="-10.785" soft_upper_limit="10.698" />
</joint>

<link name="right_back_leg">
  <visual>
    <geometry>
      <mesh filename="package://dragon_description/meshes/upper_leg.stl"/>
    </geometry>
    <origin xyz="0 0 0" rpy="1.570796327 0 0" />
  </visual>
  <collision>
    <geometry>
      <mesh filename="package://dragon_description/meshes/upper_leg.stl"/>
    </geometry>
    <origin xyz="0 0 0" rpy="1.570796327 0 0" />
  </collision>
  <inertial>
    <origin xyz="0 0 -0.1325" rpy="1.570796327 0 0" />
    <mass value="0.58240446"/>
    <inertia ixx="0.004146058" ixy="0.000104152" ixz="-0.000001286" iyy="0.000305157" iyz="-0.00000174" izz="0.0042282"/>
  </inertial>
</link>
<joint name="right_back_hip" type="revolute">
  <parent link="right_back_upper"/>
  <child link="right_back_leg"/>
  <axis xyz="0 1 0"/>
  <origin xyz="0 0 0" rpy="0 0 0"/>
  <dynamics damping="0.1" friction="0"/>
  <limit lower="-0.78539815" upper="0.698131689" effort="100" velocity="10"/>
  <safety_controller k_position="100" k_velocity="100" soft_lower_limit="-10.785" soft_upper_limit="10.698" />
</joint>

<link name="left_front_shine">
  <visual>
    <geometry>
      <mesh filename="package://dragon_description/meshes/front_shine.stl"/>
    </geometry>
    <origin xyz="0 0 0" rpy="0 3.14159 -1.570796327" />
  </visual>
  <collision>
    <geometry>
      <mesh filename="package://dragon_description/meshes/front_shine.stl"/>
    </geometry>
    <origin xyz="0 0 0" rpy="0 3.14159 -1.570796327" />
  </collision>
  <inertial>
    <origin xyz="0 0 -0.113" rpy="0 3.14159 -1.570796327" />
    <mass value="0.29186134"/>
    <inertia ixx="0.001325132" ixy="0" ixz="-0.000000355" iyy="0.001312476" iyz="-0.000006983" izz="0.000039606"/>
  </inertial>
</link>
<joint name="left_front_knee" type="revolute">
  <parent link="left_front_leg"/>
  <child link="left_front_shine"/>
  <axis xyz="0 1 0"/>
  <origin xyz="0 0 -0.275" rpy="0 0 0"/>
  <dynamics damping="0.1" friction="0"/>
  <limit lower="-1.919862144" upper="-0.174532922" effort="100" velocity="10"/>
  <safety_controller k_position="100" k_velocity="100" soft_lower_limit="-11.919" soft_upper_limit="9.83" />
</joint>

<link name="right_front_shine">
  <visual>
    <geometry>
      <mesh filename="package://dragon_description/meshes/front_shine.stl"/>
    </geometry>
    <origin xyz="0 0 0" rpy="0 3.14159 -1.570796327" />
  </visual>
  <collision>
    <geometry>
      <mesh filename="package://dragon_description/meshes/front_shine.stl"/>
    </geometry>
    <origin xyz="0 0 0" rpy="0 3.14159 -1.570796327" />
  </collision>
  <inertial>
    <origin xyz="0 0 -0.113" rpy="0 3.14159 -1.570796327" />
    <mass value="0.29186134"/>
    <inertia ixx="0.001325132" ixy="0" ixz="-0.000000355" iyy="0.001312476" iyz="-0.000006983" izz="0.000039606"/>
  </inertial>
</link>
<joint name="right_front_knee" type="revolute">
  <parent link="right_front_leg"/>
  <child link="right_front_shine"/>
  <axis xyz="0 1 0"/>
  <origin xyz="0 0 -0.275" rpy="0 0 0"/>
  <dynamics damping="0.1" friction="0"/>
  <limit lower="-1.919862144" upper="-0.174532922" effort="100" velocity="10"/>
  <safety_controller k_position="100" k_velocity="100" soft_lower_limit="-11.919" soft_upper_limit="9.83" />
</joint>

<link name="left_back_shine">
  <visual>
    <geometry>
      <mesh filename="package://dragon_description/meshes/back_shine.stl"/>
    </geometry>
    <origin xyz="0 0 0" rpy="0 0 1.570796327" />
  </visual>
  <collision>
    <geometry>
      <mesh filename="package://dragon_description/meshes/back_shine.stl"/>
    </geometry>
    <origin xyz="0 0 0" rpy="0 0 1.570796327" />
  </collision>
  <inertial>
    <origin xyz="0 0 -0.133" rpy="0 0 1.570796327" />
    <mass value="0.29186134"/>
    <inertia ixx="0.001782767" ixy="-0.000000069" ixz="0.000008825" iyy="0.001756178" iyz="-0.000011054" izz="0.000048789"/>
  </inertial>
</link>
<joint name="left_back_knee" type="revolute">
  <parent link="left_back_leg"/>
  <child link="left_back_shine"/>
  <axis xyz="0 1 0"/>
  <origin xyz="0 0 -0.275" rpy="0 0 0"/>
  <dynamics damping="0.1" friction="0"/>
  <limit lower="0.174532922" upper="1.919862144" effort="100" velocity="10"/>
  <safety_controller k_position="100" k_velocity="100" soft_lower_limit="-9.83" soft_upper_limit="11.919" />
</joint>

<link name="right_back_shine">
  <visual>
    <geometry>
      <mesh filename="package://dragon_description/meshes/back_shine.stl"/>
    </geometry>
    <origin xyz="0 0 0" rpy="0 0 1.570796327" />
  </visual>
  <collision>
    <geometry>
      <mesh filename="package://dragon_description/meshes/back_shine.stl"/>
    </geometry>
    <origin xyz="0 0 0" rpy="0 0 1.570796327" />
  </collision>
  <inertial>
    <origin xyz="0 0 -0.133" rpy="0 0 1.570796327" />
    <mass value="0.29186134"/>
    <inertia ixx="0.001782767" ixy="-0.000000069" ixz="0.000008825" iyy="0.001756178" iyz="-0.000011054" izz="0.000048789"/>
  </inertial>
</link>
<joint name="right_back_knee" type="revolute">
  <parent link="right_back_leg"/>
  <child link="right_back_shine"/>
  <axis xyz="0 1 0"/>
  <origin xyz="0 0 -0.275" rpy="0 0 0"/>
  <dynamics damping="0.1" friction="0"/>
  <limit lower="0.174532922" upper="1.919862144" effort="100" velocity="10"/>
  <safety_controller k_position="100" k_velocity="100" soft_lower_limit="-9.83" soft_upper_limit="11.919" />
</joint>

<link name="left_front_feet">
  <visual>
    <geometry>
      <sphere radius="0.01"/>
    </geometry>
    <origin xyz="0 0 0" rpy="0 0 0" />
  </visual>
  <collision>
    <geometry>
      <sphere radius="0.01"/>
    </geometry>
    <origin xyz="0 0 0" rpy="0 0 0" />
  </collision>
  <inertial>
    <origin xyz="0 0 0" rpy="0 0 0" />
    <mass value="0.1"/>
    <inertia ixx="0.000004" ixy="0.0" ixz="0.0" iyy="0.000004" iyz="0.0" izz="0.000004"/>
  </inertial>
</link>
<joint name="left_front_foot" type="revolute">
  <parent link="left_front_shine"/>
  <child link="left_front_feet"/>
  <origin xyz="0 0 -0.226" rpy="0 0 0"/>
  <dynamics damping="0.1" friction="0"/>
  <limit lower="0" upper="0" effort="0" velocity="0"/>
</joint>

<link name="right_front_feet">
  <visual>
    <geometry>
      <sphere radius="0.01"/>
    </geometry>
    <origin xyz="0 0 0" rpy="0 0 0" />
  </visual>
  <collision>
    <geometry>
      <sphere radius="0.01"/>
    </geometry>
    <origin xyz="0 0 0" rpy="0 0 0" />
  </collision>
  <inertial>
    <origin xyz="0 0 0" rpy="0 0 0" />
    <mass value="0.1"/>
    <inertia ixx="0.000004" ixy="0.0" ixz="0.0" iyy="0.000004" iyz="0.0" izz="0.000004"/>
  </inertial>
</link>
<joint name="right_front_foot" type="revolute">
  <parent link="right_front_shine"/>
  <child link="right_front_feet"/>
  <origin xyz="0 0 -0.226" rpy="0 0 0"/>
  <dynamics damping="0.1" friction="0"/>
  <limit lower="0" upper="0" effort="0" velocity="0"/>
</joint>

<link name="left_back_feet">
  <visual>
    <geometry>
      <sphere radius="0.01"/>
    </geometry>
    <origin xyz="0 0 0" rpy="0 0 0" />
  </visual>
  <collision>
    <geometry>
      <sphere radius="0.01"/>
    </geometry>
    <origin xyz="0 0 0" rpy="0 0 0" />
  </collision>
  <inertial>
    <origin xyz="0 0 0" rpy="0 0 0" />
    <mass value="0.1"/>
    <inertia ixx="0.000004" ixy="0.0" ixz="0.0" iyy="0.000004" iyz="0.0" izz="0.000004"/>
  </inertial>
</link>
<joint name="left_back_foot" type="revolute">
  <parent link="left_back_shine"/>
  <child link="left_back_feet"/>
  <origin xyz="0 0 -0.266" rpy="0 0 0"/>
  <dynamics damping="0.1" friction="0"/>
  <limit lower="0" upper="0" effort="0" velocity="0"/>
</joint>

<link name="right_back_feet">
  <visual>
    <geometry>
      <sphere radius="0.01"/>
    </geometry>
    <origin xyz="0 0 0" rpy="0 0 0" />
  </visual>
  <collision>
    <geometry>
      <sphere radius="0.01"/>
    </geometry>
    <origin xyz="0 0 0" rpy="0 0 0" />
  </collision>
  <inertial>
    <origin xyz="0 0 0" rpy="0 0 0" />
    <mass value="0.1"/>
    <inertia ixx="0.000004" ixy="0.0" ixz="0.0" iyy="0.000004" iyz="0.0" izz="0.000004"/>
  </inertial>
</link>
<joint name="right_back_foot" type="revolute">
  <parent link="right_back_shine"/>
  <child link="right_back_feet"/>
  <origin xyz="0 0 -0.266" rpy="0 0 0"/>
  <dynamics damping="0.1" friction="0"/>
  <limit lower="0" upper="0" effort="0" velocity="0"/>
</joint>

</robot>